{
  size: [9, 5, 9],
  entities: [],
  blocks: [
    {pos: [0, 0, 0], state: 1},
    {pos: [1, 0, 0], state: 1},
    {pos: [2, 0, 0], state: 1},
    {pos: [3, 0, 0], state: 1},
    {nbt: {final_state: "minecraft:stone_bricks", id: "minecraft:jigsaw", joint: "rollable", name: "minecraft:bottom", pool: "minecraft:empty", target: "minecraft:bottom"}, pos: [4, 0, 0], state: 2},
    {pos: [5, 0, 0], state: 1},
    {pos: [6, 0, 0], state: 1},
    {pos: [7, 0, 0], state: 1},
    {pos: [8, 0, 0], state: 1},
    {pos: [0, 0, 1], state: 1},
    {pos: [1, 0, 1], state: 1},
    {pos: [2, 0, 1], state: 1},
    {pos: [3, 0, 1], state: 1},
    {pos: [4, 0, 1], state: 1},
    {pos: [5, 0, 1], state: 1},
    {pos: [6, 0, 1], state: 1},
    {pos: [7, 0, 1], state: 1},
    {pos: [8, 0, 1], state: 1},
    {pos: [0, 0, 2], state: 1},
    {pos: [1, 0, 2], state: 1},
    {pos: [2, 0, 2], state: 1},
    {pos: [3, 0, 2], state: 1},
    {pos: [4, 0, 2], state: 1},
    {pos: [5, 0, 2], state: 1},
    {pos: [6, 0, 2], state: 1},
    {pos: [7, 0, 2], state: 1},
    {pos: [8, 0, 2], state: 1},
    {pos: [0, 0, 3], state: 1},
    {pos: [1, 0, 3], state: 1},
    {pos: [2, 0, 3], state: 1},
    {pos: [3, 0, 3], state: 1},
    {pos: [4, 0, 3], state: 1},
    {pos: [5, 0, 3], state: 1},
    {pos: [6, 0, 3], state: 1},
    {pos: [7, 0, 3], state: 1},
    {pos: [8, 0, 3], state: 1},
    {pos: [0, 0, 4], state: 1},
    {pos: [1, 0, 4], state: 1},
    {pos: [2, 0, 4], state: 1},
    {pos: [3, 0, 4], state: 1},
    {pos: [4, 0, 4], state: 1},
    {pos: [5, 0, 4], state: 1},
    {pos: [6, 0, 4], state: 1},
    {pos: [7, 0, 4], state: 1},
    {pos: [8, 0, 4], state: 1},
    {pos: [0, 0, 5], state: 1},
    {pos: [1, 0, 5], state: 1},
    {pos: [2, 0, 5], state: 1},
    {pos: [3, 0, 5], state: 1},
    {pos: [4, 0, 5], state: 1},
    {pos: [5, 0, 5], state: 1},
    {pos: [6, 0, 5], state: 1},
    {pos: [7, 0, 5], state: 1},
    {pos: [8, 0, 5], state: 1},
    {pos: [0, 0, 6], state: 1},
    {pos: [1, 0, 6], state: 1},
    {pos: [2, 0, 6], state: 1},
    {pos: [3, 0, 6], state: 1},
    {pos: [4, 0, 6], state: 1},
    {pos: [5, 0, 6], state: 1},
    {pos: [6, 0, 6], state: 1},
    {pos: [7, 0, 6], state: 1},
    {pos: [8, 0, 6], state: 1},
    {pos: [0, 0, 7], state: 1},
    {pos: [1, 0, 7], state: 1},
    {pos: [2, 0, 7], state: 1},
    {pos: [3, 0, 7], state: 1},
    {pos: [4, 0, 7], state: 1},
    {pos: [5, 0, 7], state: 1},
    {pos: [6, 0, 7], state: 1},
    {pos: [7, 0, 7], state: 1},
    {pos: [8, 0, 7], state: 1},
    {pos: [0, 0, 8], state: 1},
    {pos: [1, 0, 8], state: 1},
    {pos: [2, 0, 8], state: 1},
    {pos: [3, 0, 8], state: 1},
    {pos: [4, 0, 8], state: 1},
    {pos: [5, 0, 8], state: 1},
    {pos: [6, 0, 8], state: 1},
    {pos: [7, 0, 8], state: 1},
    {pos: [8, 0, 8], state: 1},

    {pos: [1, 1, 1], state: 1},
    {pos: [2, 1, 1], state: 1},
    {pos: [3, 1, 1], state: 1},
    {pos: [4, 1, 1], state: 1},
    {pos: [5, 1, 1], state: 1},
    {pos: [6, 1, 1], state: 1},
    {pos: [7, 1, 1], state: 1},
    {pos: [1, 1, 2], state: 1},
    {pos: [2, 1, 2], state: 1},
    {pos: [3, 1, 2], state: 1},
    {pos: [4, 1, 2], state: 1},
    {pos: [5, 1, 2], state: 1},
    {pos: [6, 1, 2], state: 1},
    {pos: [7, 1, 2], state: 1},
    {pos: [1, 1, 3], state: 1},
    {pos: [2, 1, 3], state: 1},
    {pos: [3, 1, 3], state: 1},
    {pos: [4, 1, 3], state: 1},
    {pos: [5, 1, 3], state: 1},
    {pos: [6, 1, 3], state: 1},
    {pos: [7, 1, 3], state: 1},
    {pos: [1, 1, 4], state: 1},
    {pos: [2, 1, 4], state: 1},
    {pos: [3, 1, 4], state: 1},
    {pos: [4, 1, 4], state: 1},
    {pos: [5, 1, 4], state: 1},
    {pos: [6, 1, 4], state: 1},
    {pos: [7, 1, 4], state: 1},
    {pos: [1, 1, 5], state: 1},
    {pos: [2, 1, 5], state: 1},
    {pos: [3, 1, 5], state: 1},
    {pos: [4, 1, 5], state: 1},
    {pos: [5, 1, 5], state: 1},
    {pos: [6, 1, 5], state: 1},
    {pos: [7, 1, 5], state: 1},
    {pos: [1, 1, 6], state: 1},
    {pos: [2, 1, 6], state: 1},
    {pos: [3, 1, 6], state: 1},
    {pos: [4, 1, 6], state: 1},
    {pos: [5, 1, 6], state: 1},
    {pos: [6, 1, 6], state: 1},
    {pos: [7, 1, 6], state: 1},
    {pos: [1, 1, 7], state: 1},
    {pos: [2, 1, 7], state: 1},
    {pos: [3, 1, 7], state: 1},
    {pos: [4, 1, 7], state: 1},
    {pos: [5, 1, 7], state: 1},
    {pos: [6, 1, 7], state: 1},
    {pos: [7, 1, 7], state: 1},

    {pos: [2, 2, 2], state: 1},
    {pos: [3, 2, 2], state: 1},
    {pos: [4, 2, 2], state: 1},
    {pos: [5, 2, 2], state: 1},
    {pos: [6, 2, 2], state: 1},
    {pos: [2, 2, 3], state: 1},
    {pos: [3, 2, 3], state: 1},
    {pos: [4, 2, 3], state: 1},
    {pos: [5, 2, 3], state: 1},
    {pos: [6, 2, 3], state: 1},
    {pos: [2, 2, 4], state: 1},
    {pos: [3, 2, 4], state: 1},
    {pos: [4, 2, 4], state: 1},
    {pos: [5, 2, 4], state: 1},
    {pos: [6, 2, 4], state: 1},
    {pos: [2, 2, 5], state: 1},
    {pos: [3, 2, 5], state: 1},
    {pos: [4, 2, 5], state: 1},
    {pos: [5, 2, 5], state: 1},
    {pos: [6, 2, 5], state: 1},
    {pos: [2, 2, 6], state: 1},
    {pos: [3, 2, 6], state: 1},
    {pos: [4, 2, 6], state: 1},
    {pos: [5, 2, 6], state: 1},
    {pos: [6, 2, 6], state: 1},

    {pos: [3, 3, 3], state: 4},
    {pos: [4, 3, 3], state: 6},
    {pos: [5, 3, 3], state: 4},
    {pos: [3, 3, 4], state: 8},
    {pos: [4, 3, 4], state: 3},
    {pos: [5, 3, 4], state: 9},
    {pos: [3, 3, 5], state: 4},
    {pos: [4, 3, 5], state: 7},
    {pos: [5, 3, 5], state: 4},
    {pos: [4, 4, 4], state: 10}
  ],
  palette: [
    {Name: "minecraft:air"},
    {Name: "minecraft:stone_bricks"},
    {Name: "minecraft:jigsaw", Properties: {orientation: "down_south"}},
    {Name: "minecraft:waxed_copper_block"},
    {Name: "minecraft:waxed_cut_copper", Properties: {axis: "y"}},
    {Name: "minecraft:waxed_cut_copper_slab", Properties: {type: "bottom", waterlogged: "false"}},
    {Name: "minecraft:waxed_cut_copper_stairs", Properties: {facing: "north", half: "bottom", shape: "straight", waterlogged: "false"}},
    {Name: "minecraft:waxed_cut_copper_stairs", Properties: {facing: "south", half: "bottom", shape: "straight", waterlogged: "false"}},
    {Name: "minecraft:waxed_cut_copper_stairs", Properties: {facing: "west", half: "bottom", shape: "straight", waterlogged: "false"}},
    {Name: "minecraft:waxed_cut_copper_stairs", Properties: {facing: "east", half: "bottom", shape: "straight", waterlogged: "false"}},
    {Name: "dimensionalfonts:dimensional_font"}
  ]
}
