{
  size: [7, 5, 7],
  entities: [],
  blocks: [
    {pos: [0, 0, 0], state: 3},
    {pos: [1, 0, 0], state: 3},
    {pos: [2, 0, 0], state: 3},
    {nbt: {final_state: "minecraft:waxed_cut_copper", id: "minecraft:jigsaw", joint: "rollable", name: "minecraft:bottom", pool: "minecraft:empty", target: "minecraft:bottom"}, pos: [3, 0, 0], state: 1},
    {pos: [4, 0, 0], state: 3},
    {pos: [5, 0, 0], state: 3},
    {pos: [6, 0, 0], state: 3},
    {pos: [0, 0, 1], state: 3},
    {pos: [1, 0, 1], state: 3},
    {pos: [2, 0, 1], state: 2},
    {pos: [3, 0, 1], state: 3},
    {pos: [4, 0, 1], state: 2},
    {pos: [5, 0, 1], state: 3},
    {pos: [6, 0, 1], state: 3},
    {pos: [0, 0, 2], state: 3},
    {pos: [1, 0, 2], state: 2},
    {pos: [2, 0, 2], state: 2},
    {pos: [3, 0, 2], state: 2},
    {pos: [4, 0, 2], state: 2},
    {pos: [5, 0, 2], state: 2},
    {pos: [6, 0, 2], state: 3},
    {pos: [0, 0, 3], state: 3},
    {pos: [1, 0, 3], state: 3},
    {pos: [2, 0, 3], state: 2},
    {pos: [3, 0, 3], state: 2},
    {pos: [4, 0, 3], state: 2},
    {pos: [5, 0, 3], state: 3},
    {pos: [6, 0, 3], state: 3},
    {pos: [0, 0, 4], state: 3},
    {pos: [1, 0, 4], state: 2},
    {pos: [2, 0, 4], state: 2},
    {pos: [3, 0, 4], state: 2},
    {pos: [4, 0, 4], state: 2},
    {pos: [5, 0, 4], state: 2},
    {pos: [6, 0, 4], state: 3},
    {pos: [0, 0, 5], state: 3},
    {pos: [1, 0, 5], state: 3},
    {pos: [2, 0, 5], state: 2},
    {pos: [3, 0, 5], state: 3},
    {pos: [4, 0, 5], state: 2},
    {pos: [5, 0, 5], state: 3},
    {pos: [6, 0, 5], state: 3},
    {pos: [0, 0, 6], state: 3},
    {pos: [1, 0, 6], state: 3},
    {pos: [2, 0, 6], state: 3},
    {pos: [3, 0, 6], state: 3},
    {pos: [4, 0, 6], state: 3},
    {pos: [5, 0, 6], state: 3},
    {pos: [6, 0, 6], state: 3},
    {pos: [3, 1, 0], state: 5},
    {pos: [1, 1, 1], state: 3},
    {pos: [2, 1, 1], state: 2},
    {pos: [3, 1, 1], state: 4},
    {pos: [4, 1, 1], state: 2},
    {pos: [5, 1, 1], state: 3},
    {pos: [1, 1, 2], state: 2},
    {pos: [2, 1, 2], state: 2},
    {pos: [3, 1, 2], state: 2},
    {pos: [4, 1, 2], state: 2},
    {pos: [5, 1, 2], state: 2},
    {pos: [0, 1, 3], state: 7},
    {pos: [1, 1, 3], state: 4},
    {pos: [2, 1, 3], state: 2},
    {pos: [3, 1, 3], state: 2},
    {pos: [4, 1, 3], state: 2},
    {pos: [5, 1, 3], state: 4},
    {pos: [6, 1, 3], state: 8},
    {pos: [1, 1, 4], state: 2},
    {pos: [2, 1, 4], state: 2},
    {pos: [3, 1, 4], state: 2},
    {pos: [4, 1, 4], state: 2},
    {pos: [5, 1, 4], state: 2},
    {pos: [1, 1, 5], state: 3},
    {pos: [2, 1, 5], state: 2},
    {pos: [3, 1, 5], state: 4},
    {pos: [4, 1, 5], state: 2},
    {pos: [5, 1, 5], state: 3},
    {pos: [3, 1, 6], state: 6},
    {pos: [0, 2, 1], state: 13},
    {pos: [1, 2, 1], state: 10},
    {pos: [5, 2, 1], state: 10},
    {pos: [6, 2, 1], state: 13},
    {pos: [3, 2, 3], state: 2},
    {pos: [0, 2, 5], state: 13},
    {pos: [1, 2, 5], state: 10},
    {pos: [5, 2, 5], state: 10},
    {pos: [6, 2, 5], state: 13},
    {pos: [0, 3, 1], state: 9},
    {pos: [1, 3, 1], state: 10},
    {pos: [5, 3, 1], state: 10},
    {pos: [6, 3, 1], state: 9},
    {pos: [3, 3, 3], state: 12},
    {pos: [0, 3, 5], state: 9},
    {pos: [1, 3, 5], state: 10},
    {pos: [5, 3, 5], state: 10},
    {pos: [6, 3, 5], state: 9},
    {pos: [1, 4, 1], state: 11},
    {pos: [2, 4, 1], state: 6},
    {pos: [3, 4, 1], state: 6},
    {pos: [4, 4, 1], state: 6},
    {pos: [5, 4, 1], state: 11},
    {pos: [1, 4, 2], state: 8},
    {pos: [5, 4, 2], state: 7},
    {pos: [1, 4, 3], state: 8},
    {pos: [5, 4, 3], state: 7},
    {pos: [1, 4, 4], state: 8},
    {pos: [5, 4, 4], state: 7},
    {pos: [1, 4, 5], state: 11},
    {pos: [2, 4, 5], state: 5},
    {pos: [3, 4, 5], state: 5},
    {pos: [4, 4, 5], state: 5},
    {pos: [5, 4, 5], state: 11}
  ],
  palette: [
    {Name: "minecraft:air"},
    {Name: "minecraft:jigsaw", Properties: {orientation: "down_south"}},
    {Name: "minecraft:waxed_copper_block"},
    {Name: "minecraft:waxed_cut_copper"},
    {Name: "minecraft:packed_mud"},
    {Name: "minecraft:waxed_cut_copper_stairs", Properties: {facing: "south", half: "bottom", shape: "straight", waterlogged: "false"}},
    {Name: "minecraft:waxed_cut_copper_stairs", Properties: {facing: "north", half: "bottom", shape: "straight", waterlogged: "false"}},
    {Name: "minecraft:waxed_cut_copper_stairs", Properties: {facing: "east", half: "bottom", shape: "straight", waterlogged: "false"}},
    {Name: "minecraft:waxed_cut_copper_stairs", Properties: {facing: "west", half: "bottom", shape: "straight", waterlogged: "false"}},
    {Name: "minecraft:stripped_warped_stem", Properties: {axis: "x"}},
    {Name: "minecraft:stripped_warped_stem", Properties: {axis: "y"}},
    {Name: "minecraft:waxed_cut_copper_slab", Properties: {type: "bottom", waterlogged: "false"}},
    {Name: "dimensionalfonts:dimensional_font"},
    {Name: "minecraft:soul_lantern", Properties: {hanging: "true", waterlogged: "false"}}
  ]
}
